Workbook

Sheet README
B2: Völgyi lab mouse colony
B3: Converted from Volgyi_mice.xlsx on 2026-10-25. The original sheets are kept unchanged as "Archive ..." tabs.
B5: Sheets
B6: Breeders - one row per breeding animal (ID, line, sex, birth, cage, status, sire, dam). Age flag turns amber 60 days before 1 year and red at 1 year.
B7: Pairs - one row per breeding cage, pointing to Breeder IDs. Shows each animal's age, the oldest animal, and a "replace by" date.
B8: Cages - the cage list (same as the old Mice sheet), with real dates and a "Breeder candidate" flag for young stock.
B9: Lines - per line: allowed partner lines, whether it must always be kept, and a status (no active pair / pair over age / plan replacement).
B10: Litters - log of litters and where they were weaned. Issues - data problems found in the conversion. Settings - the age limits.
B12: Colour key
B13: Dark blue headers: columns you type in. Grey headers and grey cells: formulas, do not type there. Yellow cells on Settings: limits you can change.
B14: Age flag: green OK, amber Replace soon, red OVER AGE, blue Too young, grey NO DATE.
B16: How relatedness works
... B26: Pair IIA3c (male B016 x female B017) has pups born 2026-11-02. At weaning, 3 females go to empty cage IB9a: Cages row IB9a -> Line FL-Cx36KO, Sex F, Count 3, Birth 2026-11-02, Sire ID B016, Dam ID B017. Add a Litters row too.

Sheet Breeders
A1: ID | B1: Line | C1: Sex | D1: Birth | E1: Cage | F1: Status | G1: Sire ID | H1: Dam ID | I1: Notes | J1: Age (days) | K1: Age (months) | L1: Age flag | M1: Retire by | N1: Genotype
A2: B001 | B2: GCaMP3-Thy1 | C2: F | D2: 46048 | E2: IB2a | F2: Breeding | I2: Imported from cage IB2a | J2: =IF(D2="","",TODAY()-D2) -> 273 | K2: =IF(J2="","",ROUND(J2/30.44,1)) -> 9 | L2: =IF(A2="","",IF(OR(F2="Retired",F2="Terminated"),"-",IF(D2="","NO DATE",IF(J2>=Settings!$B$2,"OVER AGE",IF(J2>=Settings!$B$2-Settings!$B$3,"Replace soon",IF(J2<Settings!$B$4,"Too young","OK")))))) -> OK | M2: =IF(D2="","",D2+Settings!$B$2) -> 46413
A3: B002 | B3: GCaMP3-Thy1 | C3: M | D3: 46029 | E3: IB2a | F3: Breeding | I3: Imported from cage IB2a | J3: =IF(D3="","",TODAY()-D3) -> 292 | K3: =IF(J3="","",ROUND(J3/30.44,1)) -> 9.6 | L3: =IF(A3="","",IF(OR(F3="Retired",F3="Terminated"),"-",IF(D3="","NO DATE",IF(J3>=Settings!$B$2,"OVER AGE",IF(J3>=Settings!$B$2-Settings!$B$3,"Replace soon",IF(J3<Settings!$B$4,"Too young","OK")))))) -> OK | M3: =IF(D3="","",D3+Settings!$B$2) -> 46394
A4: B003 | B4: C57Bl6J | C4: F | D4: 46193 | E4: IB2d | F4: Breeding | I4: Imported from cage IB2d | J4: =IF(D4="","",TODAY()-D4) -> 128 | K4: =IF(J4="","",ROUND(J4/30.44,1)) -> 4.2 | L4: =IF(A4="","",IF(OR(F4="Retired",F4="Terminated"),"-",IF(D4="","NO DATE",IF(J4>=Settings!$B$2,"OVER AGE",IF(J4>=Settings!$B$2-Settings!$B$3,"Replace soon",IF(J4<Settings!$B$4,"Too young","OK")))))) -> OK | M4: =IF(D4="","",D4+Settings!$B$2) -> 46558
A5: B004 | B5: CX3CR1KO + Bl6 | C5: M | D5: 46141 | E5: IB2d | F5: Breeding | I5: Imported from cage IB2d | J5: =IF(D5="","",TODAY()-D5) -> 180 | K5: =IF(J5="","",ROUND(J5/30.44,1)) -> 5.9 | L5: =IF(A5="","",IF(OR(F5="Retired",F5="Terminated"),"-",IF(D5="","NO DATE",IF(J5>=Settings!$B$2,"OVER AGE",IF(J5>=Settings!$B$2-Settings!$B$3,"Replace soon",IF(J5<Settings!$B$4,"Too young","OK")))))) -> OK | M5: =IF(D5="","",D5+Settings!$B$2) -> 46506
A6: B005 | B6: C57Bl6J | C6: M | D6: 45943 | E6: IB2e | F6: Breeding | I6: Imported from cage IB2e | J6: =IF(D6="","",TODAY()-D6) -> 378 | K6: =IF(J6="","",ROUND(J6/30.44,1)) -> 12.4 | L6: =IF(A6="","",IF(OR(F6="Retired",F6="Terminated"),"-",IF(D6="","NO DATE",IF(J6>=Settings!$B$2,"OVER AGE",IF(J6>=Settings!$B$2-Settings!$B$3,"Replace soon",IF(J6<Settings!$B$4,"Too young","OK")))))) -> OVER AGE | M6: =IF(D6="","",D6+Settings!$B$2) -> 46308
A7: B006 | B7: CX3CR1KO + Bl6 | C7: F | D7: 46022 | E7: IB2e | F7: Breeding | I7: Imported from cage IB2e; Cx3cr1 (-/-) per cage card | J7: =IF(D7="","",TODAY()-D7) -> 299 | K7: =IF(J7="","",ROUND(J7/30.44,1)) -> 9.8 | L7: =IF(A7="","",IF(OR(F7="Retired",F7="Terminated"),"-",IF(D7="","NO DATE",IF(J7>=Settings!$B$2,"OVER AGE",IF(J7>=Settings!$B$2-Settings!$B$3,"Replace soon",IF(J7<Settings!$B$4,"Too young","OK")))))) -> OK | M7: =IF(D7="","",D7+Settings!$B$2) -> 46387 | N7: Cx3cr1-KO: hom
A8: B007 | B8: C57Bl6J | C8: M | D8: 45943 | E8: IB3d | F8: Breeding | I8: Imported from cage IB3d | J8: =IF(D8="","",TODAY()-D8) -> 378 | K8: =IF(J8="","",ROUND(J8/30.44,1)) -> 12.4 | L8: =IF(A8="","",IF(OR(F8="Retired",F8="Terminated"),"-",IF(D8="","NO DATE",IF(J8>=Settings!$B$2,"OVER AGE",IF(J8>=Settings!$B$2-Settings!$B$3,"Replace soon",IF(J8<Settings!$B$4,"Too young","OK")))))) -> OVER AGE | M8: =IF(D8="","",D8+Settings!$B$2) -> 46308
A9: B008 | B9: CX3CR1KO + Bl6 | C9: F | D9: 46184 | E9: IB3d | F9: Breeding | I9: Imported from cage IB3d; Cx3cr1 (-/-) per cage card | J9: =IF(D9="","",TODAY()-D9) -> 137 | K9: =IF(J9="","",ROUND(J9/30.44,1)) -> 4.5 | L9: =IF(A9="","",IF(OR(F9="Retired",F9="Terminated"),"-",IF(D9="","NO DATE",IF(J9>=Settings!$B$2,"OVER AGE",IF(J9>=Settings!$B$2-Settings!$B$3,"Replace soon",IF(J9<Settings!$B$4,"Too young","OK")))))) -> OK | M9: =IF(D9="","",D9+Settings!$B$2) -> 46549 | N9: Cx3cr1-KO: hom
A10: B009 | B10: CX3CR1KO + Bl6 | C10: F | D10: 46184 | E10: IB3d | F10: Breeding | I10: Imported from cage IB3d; Cx3cr1 (-/-) per cage card | J10: =IF(D10="","",TODAY()-D10) -> 137 | K10: =IF(J10="","",ROUND(J10/30.44,1)) -> 4.5 | L10: =IF(A10="","",IF(OR(F10="Retired",F10="Terminated"),"-",IF(D10="","NO DATE",IF(J10>=Settings!$B$2,"OVER AGE",IF(J10>=Settings!$B$2-Settings!$B$3,"Replace soon",IF(J10<Settings!$B$4,"Too young","OK")))))) -> OK | M10: =IF(D10="","",D10+Settings!$B$2) -> 46549 | N10: Cx3cr1-KO: hom
A11: B010 | B11: C57Bl6J | C11: M | D11: 45828 | E11: IB7c | F11: Retired | I11: Imported from cage IB7c. Card 2026-10-25: female removed, male alone in IB7c | J11: =IF(D11="","",TODAY()-D11) -> 493 | K11: =IF(J11="","",ROUND(J11/30.44,1)) -> 16.2 | L11: =IF(A11="","",IF(OR(F11="Retired",F11="Terminated"),"-",IF(D11="","NO DATE",IF(J11>=Settings!$B$2,"OVER AGE",IF(J11>=Settings!$B$2-Settings!$B$3,"Replace soon",IF(J11<Settings!$B$4,"Too young","OK")))))) -> - | M11: =IF(D11="","",D11+Settings!$B$2) -> 46193
A12: B011 | B12: CX3CR1KO + Bl6 | C12: F | D12: 45706 | E12: IB7c | F12: Retired | I12: Imported from cage IB7c. Crossed off the IB7c card (removed); Cx3cr1 (-/-) per cage card | J12: =IF(D12="","",TODAY()-D12) -> 615 | K12: =IF(J12="","",ROUND(J12/30.44,1)) -> 20.2 | L12: =IF(A12="","",IF(OR(F12="Retired",F12="Terminated"),"-",IF(D12="","NO DATE",IF(J12>=Settings!$B$2,"OVER AGE",IF(J12>=Settings!$B$2-Settings!$B$3,"Replace soon",IF(J12<Settings!$B$4,"Too young","OK")))))) -> - | M12: =IF(D12="","",D12+Settings!$B$2) -> 46071 | N12: Cx3cr1-KO: hom
A13: B012 | B13: Cx36KO + PV-Cre | C13: M | D13: 46117 | E13: IIA1b | F13: Breeding | I13: Imported from cage IIA1b | J13: =IF(D13="","",TODAY()-D13) -> 204 | K13: =IF(J13="","",ROUND(J13/30.44,1)) -> 6.7 | L13: =IF(A13="","",IF(OR(F13="Retired",F13="Terminated"),"-",IF(D13="","NO DATE",IF(J13>=Settings!$B$2,"OVER AGE",IF(J13>=Settings!$B$2-Settings!$B$3,"Replace soon",IF(J13<Settings!$B$4,"Too young","OK")))))) -> OK | M13: =IF(D13="","",D13+Settings!$B$2) -> 46482
A14: B013 | B14: Cx36KO + PV-Cre | C14: F | D14: 46034 | E14: IIA1b | F14: Breeding | I14: Imported from cage IIA1b | J14: =IF(D14="","",TODAY()-D14) -> 287 | K14: =IF(J14="","",ROUND(J14/30.44,1)) -> 9.4 | L14: =IF(A14="","",IF(OR(F14="Retired",F14="Terminated"),"-",IF(D14="","NO DATE",IF(J14>=Settings!$B$2,"OVER AGE",IF(J14>=Settings!$B$2-Settings!$B$3,"Replace soon",IF(J14<Settings!$B$4,"Too young","OK")))))) -> OK | M14: =IF(D14="","",D14+Settings!$B$2) -> 46399
A15: B014 | B15: PV-Cre | C15: M | D15: 45889 | E15: IIA2e | F15: Breeding | I15: Imported from cage IIA2e | J15: =IF(D15="","",TODAY()-D15) -> 432 | K15: =IF(J15="","",ROUND(J15/30.44,1)) -> 14.2 | L15: =IF(A15="","",IF(OR(F15="Retired",F15="Terminated"),"-",IF(D15="","NO DATE",IF(J15>=Settings!$B$2,"OVER AGE",IF(J15>=Settings!$B$2-Settings!$B$3,"Replace soon",IF(J15<Settings!$B$4,"Too young","OK")))))) -> OVER AGE | M15: =IF(D15="","",D15+Settings!$B$2) -> 46254
A16: B015 | B16: PV-Cre | C16: F | D16: 45944 | E16: IIA2e | F16: Breeding | I16: Imported from cage IIA2e | J16: =IF(D16="","",TODAY()-D16) -> 377 | K16: =IF(J16="","",ROUND(J16/30.44,1)) -> 12.4 | L16: =IF(A16="","",IF(OR(F16="Retired",F16="Terminated"),"-",IF(D16="","NO DATE",IF(J16>=Settings!$B$2,"OVER AGE",IF(J16>=Settings!$B$2-Settings!$B$3,"Replace soon",IF(J16<Settings!$B$4,"Too young","OK")))))) -> OVER AGE | M16: =IF(D16="","",D16+Settings!$B$2) -> 46309
A17: B016 | B17: FL-Cx36KO | C17: M | D17: 46167 | E17: IIA3c | F17: Breeding | I17: Imported from cage IIA3c | J17: =IF(D17="","",TODAY()-D17) -> 154 | K17: =IF(J17="","",ROUND(J17/30.44,1)) -> 5.1 | L17: =IF(A17="","",IF(OR(F17="Retired",F17="Terminated"),"-",IF(D17="","NO DATE",IF(J17>=Settings!$B$2,"OVER AGE",IF(J17>=Settings!$B$2-Settings!$B$3,"Replace soon",IF(J17<Settings!$B$4,"Too young","OK")))))) -> OK | M17: =IF(D17="","",D17+Settings!$B$2) -> 46532
A18: B017 | B18: FL-Cx36KO | C18: F | D18: 46189 | E18: IIA3c | F18: Breeding | I18: Imported from cage IIA3c | J18: =IF(D18="","",TODAY()-D18) -> 132 | K18: =IF(J18="","",ROUND(J18/30.44,1)) -> 4.3 | L18: =IF(A18="","",IF(OR(F18="Retired",F18="Terminated"),"-",IF(D18="","NO DATE",IF(J18>=Settings!$B$2,"OVER AGE",IF(J18>=Settings!$B$2-Settings!$B$3,"Replace soon",IF(J18<Settings!$B$4,"Too young","OK")))))) -> OK | M18: =IF(D18="","",D18+Settings!$B$2) -> 46554
A19: B018 | B19: GCaMP3-Thy1 + CarCre | C19: M | D19: 45996 | E19: IIA3e | F19: Breeding | I19: Imported from cage IIA3e. Birth from cage card (sheet had "2025.15.05") | J19: =IF(D19="","",TODAY()-D19) -> 325 | K19: =IF(J19="","",ROUND(J19/30.44,1)) -> 10.7 | L19: =IF(A19="","",IF(OR(F19="Retired",F19="Terminated"),"-",IF(D19="","NO DATE",IF(J19>=Settings!$B$2,"OVER AGE",IF(J19>=Settings!$B$2-Settings!$B$3,"Replace soon",IF(J19<Settings!$B$4,"Too young","OK")))))) -> Replace soon | M19: =IF(D19="","",D19+Settings!$B$2) -> 46361
A20: B019 | B20: GCaMP3-Thy1 + CarCre | C20: F | D20: 45979 | E20: IIA3e | F20: Breeding | I20: Imported from cage IIA3e | J20: =IF(D20="","",TODAY()-D20) -> 342 | K20: =IF(J20="","",ROUND(J20/30.44,1)) -> 11.2 | L20: =IF(A20="","",IF(OR(F20="Retired",F20="Terminated"),"-",IF(D20="","NO DATE",IF(J20>=Settings!$B$2,"OVER AGE",IF(J20>=Settings!$B$2-Settings!$B$3,"Replace soon",IF(J20<Settings!$B$4,"Too young","OK")))))) -> Replace soon | M20: =IF(D20="","",D20+Settings!$B$2) -> 46344
A21: B020 | B21: GCaMP3-Thy1 + CarCre | C21: F | D21: 45979 | E21: IIA3e | F21: Breeding | I21: Imported from cage IIA3e | J21: =IF(D21="","",TODAY()-D21) -> 342 | K21: =IF(J21="","",ROUND(J21/30.44,1)) -> 11.2 | L21: =IF(A21="","",IF(OR(F21="Retired",F21="Terminated"),"-",IF(D21="","NO DATE",IF(J21>=Settings!$B$2,"OVER AGE",IF(J21>=Settings!$B$2-Settings!$B$3,"Replace soon",IF(J21<Settings!$B$4,"Too young","OK")))))) -> Replace soon | M21: =IF(D21="","",D21+Settings!$B$2) -> 46344
A22: B021 | B22: CX3CR1KO (-/-) | C22: M | D22: 45959 | E22: IIA4a | F22: Breeding | I22: Imported from cage IIA4a | J22: =IF(D22="","",TODAY()-D22) -> 362 | K22: =IF(J22="","",ROUND(J22/30.44,1)) -> 11.9 | L22: =IF(A22="","",IF(OR(F22="Retired",F22="Terminated"),"-",IF(D22="","NO DATE",IF(J22>=Settings!$B$2,"OVER AGE",IF(J22>=Settings!$B$2-Settings!$B$3,"Replace soon",IF(J22<Settings!$B$4,"Too young","OK")))))) -> Replace soon | M22: =IF(D22="","",D22+Settings!$B$2) -> 46324 | N22: Cx3cr1-KO: hom
A23: B022 | B23: CX3CR1KO (-/-) | C23: F | D23: 46022 | E23: IIA4a | F23: Breeding | I23: Imported from cage IIA4a | J23: =IF(D23="","",TODAY()-D23) -> 299 | K23: =IF(J23="","",ROUND(J23/30.44,1)) -> 9.8 | L23: =IF(A23="","",IF(OR(F23="Retired",F23="Terminated"),"-",IF(D23="","NO DATE",IF(J23>=Settings!$B$2,"OVER AGE",IF(J23>=Settings!$B$2-Settings!$B$3,"Replace soon",IF(J23<Settings!$B$4,"Too young","OK")))))) -> OK | M23: =IF(D23="","",D23+Settings!$B$2) -> 46387 | N23: Cx3cr1-KO: hom
A24: B023 | B24: GCaMP3-Thy1 | C24: M | D24: 46006 | E24: IIA4c | F24: Breeding | I24: Imported from cage IIA4c | J24: =IF(D24="","",TODAY()-D24) -> 315 | K24: =IF(J24="","",ROUND(J24/30.44,1)) -> 10.3 | L24: =IF(A24="","",IF(OR(F24="Retired",F24="Terminated"),"-",IF(D24="","NO DATE",IF(J24>=Settings!$B$2,"OVER AGE",IF(J24>=Settings!$B$2-Settings!$B$3,"Replace soon",IF(J24<Settings!$B$4,"Too young","OK")))))) -> Replace soon | M24: =IF(D24="","",D24+Settings!$B$2) -> 46371
A25: B024 | B25: GCaMP3-Thy1 | C25: F | D25: 46060 | E25: IIA4c | F25: Breeding | I25: Imported from cage IIA4c | J25: =IF(D25="","",TODAY()-D25) -> 261 | K25: =IF(J25="","",ROUND(J25/30.44,1)) -> 8.6 | L25: =IF(A25="","",IF(OR(F25="Retired",F25="Terminated"),"-",IF(D25="","NO DATE",IF(J25>=Settings!$B$2,"OVER AGE",IF(J25>=Settings!$B$2-Settings!$B$3,"Replace soon",IF(J25<Settings!$B$4,"Too young","OK")))))) -> OK | M25: =IF(D25="","",D25+Settings!$B$2) -> 46425
A26: B025 | B26: Cas9 + PV-Cre | C26: M | D26: 45889 | E26: IIA4e | F26: Breeding | I26: Imported from cage IIA4e. Birth from cage card (sheet had 2024.08.20 for both) | J26: =IF(D26="","",TODAY()-D26) -> 432 | K26: =IF(J26="","",ROUND(J26/30.44,1)) -> 14.2 | L26: =IF(A26="","",IF(OR(F26="Retired",F26="Terminated"),"-",IF(D26="","NO DATE",IF(J26>=Settings!$B$2,"OVER AGE",IF(J26>=Settings!$B$2-Settings!$B$3,"Replace soon",IF(J26<Settings!$B$4,"Too young","OK")))))) -> OVER AGE | M26: =IF(D26="","",D26+Settings!$B$2) -> 46254
A27: B026 | B27: Cas9 + PV-Cre | C27: F | D27: 45874 | E27: IIA4e | F27: Breeding | I27: Imported from cage IIA4e. Birth from cage card (sheet had 2024.08.20 for both) | J27: =IF(D27="","",TODAY()-D27) -> 447 | K27: =IF(J27="","",ROUND(J27/30.44,1)) -> 14.7 | L27: =IF(A27="","",IF(OR(F27="Retired",F27="Terminated"),"-",IF(D27="","NO DATE",IF(J27>=Settings!$B$2,"OVER AGE",IF(J27>=Settings!$B$2-Settings!$B$3,"Replace soon",IF(J27<Settings!$B$4,"Too young","OK")))))) -> OVER AGE | M27: =IF(D27="","",D27+Settings!$B$2) -> 46239
A28: B027 | B28: C57Bl6J | C28: M | D28: 45943 | E28: IIA5b | F28: Breeding | I28: Imported from cage IIA5b | J28: =IF(D28="","",TODAY()-D28) -> 378 | K28: =IF(J28="","",ROUND(J28/30.44,1)) -> 12.4 | L28: =IF(A28="","",IF(OR(F28="Retired",F28="Terminated"),"-",IF(D28="","NO DATE",IF(J28>=Settings!$B$2,"OVER AGE",IF(J28>=Settings!$B$2-Settings!$B$3,"Replace soon",IF(J28<Settings!$B$4,"Too young","OK")))))) -> OVER AGE | M28: =IF(D28="","",D28+Settings!$B$2) -> 46308
A29: B028 | B29: CX3CR1KO + Bl6 | C29: F | D29: 46022 | E29: IIA5b | F29: Breeding | I29: Imported from cage IIA5b; Cx3cr1 (-/-) per cage card | J29: =IF(D29="","",TODAY()-D29) -> 299 | K29: =IF(J29="","",ROUND(J29/30.44,1)) -> 9.8 | L29: =IF(A29="","",IF(OR(F29="Retired",F29="Terminated"),"-",IF(D29="","NO DATE",IF(J29>=Settings!$B$2,"OVER AGE",IF(J29>=Settings!$B$2-Settings!$B$3,"Replace soon",IF(J29<Settings!$B$4,"Too young","OK")))))) -> OK | M29: =IF(D29="","",D29+Settings!$B$2) -> 46387 | N29: Cx3cr1-KO: hom
A30: B029 | B30: CX3CR1KO (-/-) | C30: M | D30: 46229 | E30: IIA6e | F30: Breeding | G30: B021 | H30: B022 | I30: Imported from cage IIA6e. Card: born 2026-07-26 in II/A/4/a -> littermates of each other | J30: =IF(D30="","",TODAY()-D30) -> 92 | K30: =IF(J30="","",ROUND(J30/30.44,1)) -> 3 | L30: =IF(A30="","",IF(OR(F30="Retired",F30="Terminated"),"-",IF(D30="","NO DATE",IF(J30>=Settings!$B$2,"OVER AGE",IF(J30>=Settings!$B$2-Settings!$B$3,"Replace soon",IF(J30<Settings!$B$4,"Too young","OK")))))) -> OK | M30: =IF(D30="","",D30+Settings!$B$2) -> 46594 | N30: Cx3cr1-KO: hom
A31: B030 | B31: CX3CR1KO (-/-) | C31: F | D31: 46229 | E31: IIA6e | F31: Breeding | G31: B021 | H31: B022 | I31: Imported from cage IIA6e. Card: born 2026-07-26 in II/A/4/a -> littermates of each other | J31: =IF(D31="","",TODAY()-D31) -> 92 | K31: =IF(J31="","",ROUND(J31/30.44,1)) -> 3 | L31: =IF(A31="","",IF(OR(F31="Retired",F31="Terminated"),"-",IF(D31="","NO DATE",IF(J31>=Settings!$B$2,"OVER AGE",IF(J31>=Settings!$B$2-Settings!$B$3,"Replace soon",IF(J31<Settings!$B$4,"Too young","OK")))))) -> OK | M31: =IF(D31="","",D31+Settings!$B$2) -> 46594 | N31: Cx3cr1-KO: hom

Sheet Pairs
A1: Pair cage | B1: Line | C1: Male ID | D1: Female 1 ID | E1: Female 2 ID | F1: Set up | G1: Status | H1: Notes | I1: Male age (d) | J1: F1 age (d) | K1: F2 age (d) | L1: Oldest (d) | M1: Age flag | N1: Replace by
A2: IB2a | B2: GCaMP3-Thy1 | C2: B002 | D2: B001 | G2: Active | I2: =IF(C2="","",IFERROR(TODAY()-INDEX(Breeders!$D$2:$D$1000,MATCH(C2,Breeders!$A$2:$A$1000,0)),"?")) -> 292 | J2: =IF(D2="","",IFERROR(TODAY()-INDEX(Breeders!$D$2:$D$1000,MATCH(D2,Breeders!$A$2:$A$1000,0)),"?")) -> 273 | K2: =IF(E2="","",IFERROR(TODAY()-INDEX(Breeders!$D$2:$D$1000,MATCH(E2,Breeders!$A$2:$A$1000,0)),"?")) | L2: =IF(COUNT(I2:K2)=0,"",MAX(I2:K2)) -> 292 | M2: =IF(OR(A2="",G2<>"Active"),"",IF(L2="","NO DATE",IF(L2>=Settings!$B$2,"OVER AGE",IF(L2>=Settings!$B$2-Settings!$B$3,"Replace soon","OK")))) -> OK | N2: =IF(OR(L2="",G2<>"Active"),"",TODAY()+Settings!$B$2-L2) -> 46394
A3: IB2d | B3: CX3CR1KO + Bl6 | C3: B004 | D3: B003 | G3: Active | I3: =IF(C3="","",IFERROR(TODAY()-INDEX(Breeders!$D$2:$D$1000,MATCH(C3,Breeders!$A$2:$A$1000,0)),"?")) -> 180 | J3: =IF(D3="","",IFERROR(TODAY()-INDEX(Breeders!$D$2:$D$1000,MATCH(D3,Breeders!$A$2:$A$1000,0)),"?")) -> 128 | K3: =IF(E3="","",IFERROR(TODAY()-INDEX(Breeders!$D$2:$D$1000,MATCH(E3,Breeders!$A$2:$A$1000,0)),"?")) | L3: =IF(COUNT(I3:K3)=0,"",MAX(I3:K3)) -> 180 | M3: =IF(OR(A3="",G3<>"Active"),"",IF(L3="","NO DATE",IF(L3>=Settings!$B$2,"OVER AGE",IF(L3>=Settings!$B$2-Settings!$B$3,"Replace soon","OK")))) -> OK | N3: =IF(OR(L3="",G3<>"Active"),"",TODAY()+Settings!$B$2-L3) -> 46506
A4: IB2e | B4: CX3CR1KO + Bl6 | C4: B005 | D4: B006 | G4: Active | I4: =IF(C4="","",IFERROR(TODAY()-INDEX(Breeders!$D$2:$D$1000,MATCH(C4,Breeders!$A$2:$A$1000,0)),"?")) -> 378 | J4: =IF(D4="","",IFERROR(TODAY()-INDEX(Breeders!$D$2:$D$1000,MATCH(D4,Breeders!$A$2:$A$1000,0)),"?")) -> 299 | K4: =IF(E4="","",IFERROR(TODAY()-INDEX(Breeders!$D$2:$D$1000,MATCH(E4,Breeders!$A$2:$A$1000,0)),"?")) | L4: =IF(COUNT(I4:K4)=0,"",MAX(I4:K4)) -> 378 | M4: =IF(OR(A4="",G4<>"Active"),"",IF(L4="","NO DATE",IF(L4>=Settings!$B$2,"OVER AGE",IF(L4>=Settings!$B$2-Settings!$B$3,"Replace soon","OK")))) -> OVER AGE | N4: =IF(OR(L4="",G4<>"Active"),"",TODAY()+Settings!$B$2-L4) -> 46308
A5: IB3d | B5: CX3CR1KO + Bl6 | C5: B007 | D5: B008 | E5: B009 | G5: Active | I5: =IF(C5="","",IFERROR(TODAY()-INDEX(Breeders!$D$2:$D$1000,MATCH(C5,Breeders!$A$2:$A$1000,0)),"?")) -> 378 | J5: =IF(D5="","",IFERROR(TODAY()-INDEX(Breeders!$D$2:$D$1000,MATCH(D5,Breeders!$A$2:$A$1000,0)),"?")) -> 137 | K5: =IF(E5="","",IFERROR(TODAY()-INDEX(Breeders!$D$2:$D$1000,MATCH(E5,Breeders!$A$2:$A$1000,0)),"?")) -> 137 | L5: =IF(COUNT(I5:K5)=0,"",MAX(I5:K5)) -> 378 | M5: =IF(OR(A5="",G5<>"Active"),"",IF(L5="","NO DATE",IF(L5>=Settings!$B$2,"OVER AGE",IF(L5>=Settings!$B$2-Settings!$B$3,"Replace soon","OK")))) -> OVER AGE | N5: =IF(OR(L5="",G5<>"Active"),"",TODAY()+Settings!$B$2-L5) -> 46308
A6: IB7c | B6: CX3CR1KO + Bl6 | C6: B010 | D6: B011 | G6: Ended | H6: Female removed (cage card 2026-10-25) | I6: =IF(C6="","",IFERROR(TODAY()-INDEX(Breeders!$D$2:$D$1000,MATCH(C6,Breeders!$A$2:$A$1000,0)),"?")) -> 493 | J6: =IF(D6="","",IFERROR(TODAY()-INDEX(Breeders!$D$2:$D$1000,MATCH(D6,Breeders!$A$2:$A$1000,0)),"?")) -> 615 | K6: =IF(E6="","",IFERROR(TODAY()-INDEX(Breeders!$D$2:$D$1000,MATCH(E6,Breeders!$A$2:$A$1000,0)),"?")) | L6: =IF(COUNT(I6:K6)=0,"",MAX(I6:K6)) -> 615 | M6: =IF(OR(A6="",G6<>"Active"),"",IF(L6="","NO DATE",IF(L6>=Settings!$B$2,"OVER AGE",IF(L6>=Settings!$B$2-Settings!$B$3,"Replace soon","OK")))) | N6: =IF(OR(L6="",G6<>"Active"),"",TODAY()+Settings!$B$2-L6)
A7: IIA1b | B7: Cx36KO + PV-Cre | C7: B012 | D7: B013 | G7: Active | I7: =IF(C7="","",IFERROR(TODAY()-INDEX(Breeders!$D$2:$D$1000,MATCH(C7,Breeders!$A$2:$A$1000,0)),"?")) -> 204 | J7: =IF(D7="","",IFERROR(TODAY()-INDEX(Breeders!$D$2:$D$1000,MATCH(D7,Breeders!$A$2:$A$1000,0)),"?")) -> 287 | K7: =IF(E7="","",IFERROR(TODAY()-INDEX(Breeders!$D$2:$D$1000,MATCH(E7,Breeders!$A$2:$A$1000,0)),"?")) | L7: =IF(COUNT(I7:K7)=0,"",MAX(I7:K7)) -> 287 | M7: =IF(OR(A7="",G7<>"Active"),"",IF(L7="","NO DATE",IF(L7>=Settings!$B$2,"OVER AGE",IF(L7>=Settings!$B$2-Settings!$B$3,"Replace soon","OK")))) -> OK | N7: =IF(OR(L7="",G7<>"Active"),"",TODAY()+Settings!$B$2-L7) -> 46399
A8: IIA2e | B8: PV-Cre | C8: B014 | D8: B015 | G8: Active | H8: Change to new pair | I8: =IF(C8="","",IFERROR(TODAY()-INDEX(Breeders!$D$2:$D$1000,MATCH(C8,Breeders!$A$2:$A$1000,0)),"?")) -> 432 | J8: =IF(D8="","",IFERROR(TODAY()-INDEX(Breeders!$D$2:$D$1000,MATCH(D8,Breeders!$A$2:$A$1000,0)),"?")) -> 377 | K8: =IF(E8="","",IFERROR(TODAY()-INDEX(Breeders!$D$2:$D$1000,MATCH(E8,Breeders!$A$2:$A$1000,0)),"?")) | L8: =IF(COUNT(I8:K8)=0,"",MAX(I8:K8)) -> 432 | M8: =IF(OR(A8="",G8<>"Active"),"",IF(L8="","NO DATE",IF(L8>=Settings!$B$2,"OVER AGE",IF(L8>=Settings!$B$2-Settings!$B$3,"Replace soon","OK")))) -> OVER AGE | N8: =IF(OR(L8="",G8<>"Active"),"",TODAY()+Settings!$B$2-L8) -> 46254
A9: IIA3c | B9: FL-Cx36KO | C9: B016 | D9: B017 | G9: Active | I9: =IF(C9="","",IFERROR(TODAY()-INDEX(Breeders!$D$2:$D$1000,MATCH(C9,Breeders!$A$2:$A$1000,0)),"?")) -> 154 | J9: =IF(D9="","",IFERROR(TODAY()-INDEX(Breeders!$D$2:$D$1000,MATCH(D9,Breeders!$A$2:$A$1000,0)),"?")) -> 132 | K9: =IF(E9="","",IFERROR(TODAY()-INDEX(Breeders!$D$2:$D$1000,MATCH(E9,Breeders!$A$2:$A$1000,0)),"?")) | L9: =IF(COUNT(I9:K9)=0,"",MAX(I9:K9)) -> 154 | M9: =IF(OR(A9="",G9<>"Active"),"",IF(L9="","NO DATE",IF(L9>=Settings!$B$2,"OVER AGE",IF(L9>=Settings!$B$2-Settings!$B$3,"Replace soon","OK")))) -> OK | N9: =IF(OR(L9="",G9<>"Active"),"",TODAY()+Settings!$B$2-L9) -> 46532
A10: IIA3e | B10: GCaMP3-Thy1 + CarCre | C10: B018 | D10: B019 | E10: B020 | G10: Active | H10: OK | I10: =IF(C10="","",IFERROR(TODAY()-INDEX(Breeders!$D$2:$D$1000,MATCH(C10,Breeders!$A$2:$A$1000,0)),"?")) -> 325 | J10: =IF(D10="","",IFERROR(TODAY()-INDEX(Breeders!$D$2:$D$1000,MATCH(D10,Breeders!$A$2:$A$1000,0)),"?")) -> 342 | K10: =IF(E10="","",IFERROR(TODAY()-INDEX(Breeders!$D$2:$D$1000,MATCH(E10,Breeders!$A$2:$A$1000,0)),"?")) -> 342 | L10: =IF(COUNT(I10:K10)=0,"",MAX(I10:K10)) -> 342 | M10: =IF(OR(A10="",G10<>"Active"),"",IF(L10="","NO DATE",IF(L10>=Settings!$B$2,"OVER AGE",IF(L10>=Settings!$B$2-Settings!$B$3,"Replace soon","OK")))) -> Replace soon | N10: =IF(OR(L10="",G10<>"Active"),"",TODAY()+Settings!$B$2-L10) -> 46344
A11: IIA4a | B11: CX3CR1KO (-/-) | C11: B021 | D11: B022 | G11: Active | I11: =IF(C11="","",IFERROR(TODAY()-INDEX(Breeders!$D$2:$D$1000,MATCH(C11,Breeders!$A$2:$A$1000,0)),"?")) -> 362 | J11: =IF(D11="","",IFERROR(TODAY()-INDEX(Breeders!$D$2:$D$1000,MATCH(D11,Breeders!$A$2:$A$1000,0)),"?")) -> 299 | K11: =IF(E11="","",IFERROR(TODAY()-INDEX(Breeders!$D$2:$D$1000,MATCH(E11,Breeders!$A$2:$A$1000,0)),"?")) | L11: =IF(COUNT(I11:K11)=0,"",MAX(I11:K11)) -> 362 | M11: =IF(OR(A11="",G11<>"Active"),"",IF(L11="","NO DATE",IF(L11>=Settings!$B$2,"OVER AGE",IF(L11>=Settings!$B$2-Settings!$B$3,"Replace soon","OK")))) -> Replace soon | N11: =IF(OR(L11="",G11<>"Active"),"",TODAY()+Settings!$B$2-L11) -> 46324
A12: IIA4c | B12: GCaMP3-Thy1 | C12: B023 | D12: B024 | G12: Active | H12: OK | I12: =IF(C12="","",IFERROR(TODAY()-INDEX(Breeders!$D$2:$D$1000,MATCH(C12,Breeders!$A$2:$A$1000,0)),"?")) -> 315 | J12: =IF(D12="","",IFERROR(TODAY()-INDEX(Breeders!$D$2:$D$1000,MATCH(D12,Breeders!$A$2:$A$1000,0)),"?")) -> 261 | K12: =IF(E12="","",IFERROR(TODAY()-INDEX(Breeders!$D$2:$D$1000,MATCH(E12,Breeders!$A$2:$A$1000,0)),"?")) | L12: =IF(COUNT(I12:K12)=0,"",MAX(I12:K12)) -> 315 | M12: =IF(OR(A12="",G12<>"Active"),"",IF(L12="","NO DATE",IF(L12>=Settings!$B$2,"OVER AGE",IF(L12>=Settings!$B$2-Settings!$B$3,"Replace soon","OK")))) -> Replace soon | N12: =IF(OR(L12="",G12<>"Active"),"",TODAY()+Settings!$B$2-L12) -> 46371
A13: IIA4e | B13: Cas9 + PV-Cre | C13: B025 | D13: B026 | G13: Active | I13: =IF(C13="","",IFERROR(TODAY()-INDEX(Breeders!$D$2:$D$1000,MATCH(C13,Breeders!$A$2:$A$1000,0)),"?")) -> 432 | J13: =IF(D13="","",IFERROR(TODAY()-INDEX(Breeders!$D$2:$D$1000,MATCH(D13,Breeders!$A$2:$A$1000,0)),"?")) -> 447 | K13: =IF(E13="","",IFERROR(TODAY()-INDEX(Breeders!$D$2:$D$1000,MATCH(E13,Breeders!$A$2:$A$1000,0)),"?")) | L13: =IF(COUNT(I13:K13)=0,"",MAX(I13:K13)) -> 447 | M13: =IF(OR(A13="",G13<>"Active"),"",IF(L13="","NO DATE",IF(L13>=Settings!$B$2,"OVER AGE",IF(L13>=Settings!$B$2-Settings!$B$3,"Replace soon","OK")))) -> OVER AGE | N13: =IF(OR(L13="",G13<>"Active"),"",TODAY()+Settings!$B$2-L13) -> 46239
A14: IIA5b | B14: CX3CR1KO + Bl6 | C14: B027 | D14: B028 | G14: Active | I14: =IF(C14="","",IFERROR(TODAY()-INDEX(Breeders!$D$2:$D$1000,MATCH(C14,Breeders!$A$2:$A$1000,0)),"?")) -> 378 | J14: =IF(D14="","",IFERROR(TODAY()-INDEX(Breeders!$D$2:$D$1000,MATCH(D14,Breeders!$A$2:$A$1000,0)),"?")) -> 299 | K14: =IF(E14="","",IFERROR(TODAY()-INDEX(Breeders!$D$2:$D$1000,MATCH(E14,Breeders!$A$2:$A$1000,0)),"?")) | L14: =IF(COUNT(I14:K14)=0,"",MAX(I14:K14)) -> 378 | M14: =IF(OR(A14="",G14<>"Active"),"",IF(L14="","NO DATE",IF(L14>=Settings!$B$2,"OVER AGE",IF(L14>=Settings!$B$2-Settings!$B$3,"Replace soon","OK")))) -> OVER AGE | N14: =IF(OR(L14="",G14<>"Active"),"",TODAY()+Settings!$B$2-L14) -> 46308
A15: IIA6e | B15: CX3CR1KO (-/-) | C15: B029 | D15: B030 | G15: Active | I15: =IF(C15="","",IFERROR(TODAY()-INDEX(Breeders!$D$2:$D$1000,MATCH(C15,Breeders!$A$2:$A$1000,0)),"?")) -> 92 | J15: =IF(D15="","",IFERROR(TODAY()-INDEX(Breeders!$D$2:$D$1000,MATCH(D15,Breeders!$A$2:$A$1000,0)),"?")) -> 92 | K15: =IF(E15="","",IFERROR(TODAY()-INDEX(Breeders!$D$2:$D$1000,MATCH(E15,Breeders!$A$2:$A$1000,0)),"?")) | L15: =IF(COUNT(I15:K15)=0,"",MAX(I15:K15)) -> 92 | M15: =IF(OR(A15="",G15<>"Active"),"",IF(L15="","NO DATE",IF(L15>=Settings!$B$2,"OVER AGE",IF(L15>=Settings!$B$2-Settings!$B$3,"Replace soon","OK")))) -> OK | N15: =IF(OR(L15="",G15<>"Active"),"",TODAY()+Settings!$B$2-L15) -> 46594

Sheet Cages
A1: Cage | B1: Line | C1: Line as written | D1: Sex | E1: Count | F1: Birth | G1: Age (days) | H1: Age (months) | I1: Breeder candidate | J1: Sire ID | K1: Dam ID | L1: Note | M1: Reserved for | N1: Genotype
A2: IB1b | B2: CX3CR1KO + Bl6 | C2: CX3CR1KO+Bl6 | D2: F | E2: 2 | F2: 46269 | G2: =IF(F2="","",TODAY()-F2) -> 52 | H2: =IF(G2="","",ROUND(G2/30.44,1)) -> 1.7 | I2: =IF(OR(F2="",D2="TP",D2=""),"",IF(G2<Settings!$B$4,"Too young",IF(G2<=Settings!$B$5,"Yes","Too old"))) -> Yes | J2: B005 | K2: B006
A3: IB1c | B3: CX3CR1KO + Bl6 | C3: CX3CR1KO+Bl6 | D3: M | E3: 2 | F3: 46269 | G3: =IF(F3="","",TODAY()-F3) -> 52 | H3: =IF(G3="","",ROUND(G3/30.44,1)) -> 1.7 | I3: =IF(OR(F3="",D3="TP",D3=""),"",IF(G3<Settings!$B$4,"Too young",IF(G3<=Settings!$B$5,"Yes","Too old"))) -> Yes | J3: B005 | K3: B006
A4: IB1d | G4: =IF(F4="","",TODAY()-F4) | H4: =IF(G4="","",ROUND(G4/30.44,1)) | I4: =IF(OR(F4="",D4="TP",D4=""),"",IF(G4<Settings!$B$4,"Too young",IF(G4<=Settings!$B$5,"Yes","Too old")))
A5: IB1e | G5: =IF(F5="","",TODAY()-F5) | H5: =IF(G5="","",ROUND(G5/30.44,1)) | I5: =IF(OR(F5="",D5="TP",D5=""),"",IF(G5<Settings!$B$4,"Too young",IF(G5<=Settings!$B$5,"Yes","Too old")))
A6: IB2a | B6: GCaMP3-Thy1 | C6: GCaMP3Thy1 | D6: TP | E6: 2 | G6: =IF(F6="","",TODAY()-F6) | H6: =IF(G6="","",ROUND(G6/30.44,1)) | I6: =IF(OR(F6="",D6="TP",D6=""),"",IF(G6<Settings!$B$4,"Too young",IF(G6<=Settings!$B$5,"Yes","Too old"))) | L6: Breeding pair - see Pairs
A7: IB2b | B7: GCaMP3-Thy1 + CarCre | C7: GCaMP3Thy1 + CarCre | D7: F | E7: 3 | F7: 46269 | G7: =IF(F7="","",TODAY()-F7) -> 52 | H7: =IF(G7="","",ROUND(G7/30.44,1)) -> 1.7 | I7: =IF(OR(F7="",D7="TP",D7=""),"",IF(G7<Settings!$B$4,"Too young",IF(G7<=Settings!$B$5,"Yes","Too old"))) -> Yes | J7: B018
A8: IB2c | G8: =IF(F8="","",TODAY()-F8) | H8: =IF(G8="","",ROUND(G8/30.44,1)) | I8: =IF(OR(F8="",D8="TP",D8=""),"",IF(G8<Settings!$B$4,"Too young",IF(G8<=Settings!$B$5,"Yes","Too old")))
A9: IB2d | B9: CX3CR1KO + Bl6 | C9: CX3CR1KO + BL6 | D9: TP | E9: 2 | G9: =IF(F9="","",TODAY()-F9) | H9: =IF(G9="","",ROUND(G9/30.44,1)) | I9: =IF(OR(F9="",D9="TP",D9=""),"",IF(G9<Settings!$B$4,"Too young",IF(G9<=Settings!$B$5,"Yes","Too old"))) | L9: Breeding pair - see Pairs
A10: IB2e | B10: CX3CR1KO + Bl6 | C10: CX3CR1KO + BL6 | D10: TP | E10: 2 | G10: =IF(F10="","",TODAY()-F10) | H10: =IF(G10="","",ROUND(G10/30.44,1)) | I10: =IF(OR(F10="",D10="TP",D10=""),"",IF(G10<Settings!$B$4,"Too young",IF(G10<=Settings!$B$5,"Yes","Too old"))) | L10: Breeding pair - see Pairs
A11: IB3a | B11: GCaMP3-Thy1 | C11: GCaMP3Thy1 | D11: F | E11: 2 | F11: 46272 | G11: =IF(F11="","",TODAY()-F11) -> 49 | H11: =IF(G11="","",ROUND(G11/30.44,1)) -> 1.6 | I11: =IF(OR(F11="",D11="TP",D11=""),"",IF(G11<Settings!$B$4,"Too young",IF(G11<=Settings!$B$5,"Yes","Too old"))) -> Yes | J11: B002 | K11: B001
A12: IB3b | B12: C57Bl6J | C12: C57Bl6J | D12: F | E12: 4 | F12: 45943 | G12: =IF(F12="","",TODAY()-F12) -> 378 | H12: =IF(G12="","",ROUND(G12/30.44,1)) -> 12.4 | I12: =IF(OR(F12="",D12="TP",D12=""),"",IF(G12<Settings!$B$4,"Too young",IF(G12<=Settings!$B$5,"Yes","Too old"))) -> Too old | L12: terminate or use
A13: IB3c | B13: GCaMP3-Thy1 | C13: GCaMP3Thy1 | D13: M | E13: 3 | F13: 46272 | G13: =IF(F13="","",TODAY()-F13) -> 49 | H13: =IF(G13="","",ROUND(G13/30.44,1)) -> 1.6 | I13: =IF(OR(F13="",D13="TP",D13=""),"",IF(G13<Settings!$B$4,"Too young",IF(G13<=Settings!$B$5,"Yes","Too old"))) -> Yes | J13: B002 | K13: B001
A14: IB3d | B14: CX3CR1KO + Bl6 | C14: CX3CR1KO + BL6 | D14: TP | E14: 3 | G14: =IF(F14="","",TODAY()-F14) | H14: =IF(G14="","",ROUND(G14/30.44,1)) | I14: =IF(OR(F14="",D14="TP",D14=""),"",IF(G14<Settings!$B$4,"Too young",IF(G14<=Settings!$B$5,"Yes","Too old"))) | L14: Breeding pair - see Pairs
A15: IB3e | G15: =IF(F15="","",TODAY()-F15) | H15: =IF(G15="","",ROUND(G15/30.44,1)) | I15: =IF(OR(F15="",D15="TP",D15=""),"",IF(G15<Settings!$B$4,"Too young",IF(G15<=Settings!$B$5,"Yes","Too old")))
A16: IB4a | B16: C57Bl6J | C16: C57Bl6J | D16: M | E16: 2 | F16: 45943 | G16: =IF(F16="","",TODAY()-F16) -> 378 | H16: =IF(G16="","",ROUND(G16/30.44,1)) -> 12.4 | I16: =IF(OR(F16="",D16="TP",D16=""),"",IF(G16<Settings!$B$4,"Too young",IF(G16<=Settings!$B$5,"Yes","Too old"))) -> Too old | L16: terminate or use
A17: IB4b | B17: CX3CR1KO + Bl6 | C17: CX3CR1KO+Bl6 | D17: M | E17: 2 | F17: 46241 | G17: =IF(F17="","",TODAY()-F17) -> 80 | H17: =IF(G17="","",ROUND(G17/30.44,1)) -> 2.6 | I17: =IF(OR(F17="",D17="TP",D17=""),"",IF(G17<Settings!$B$4,"Too young",IF(G17<=Settings!$B$5,"Yes","Too old"))) -> Yes | J17: B005 | K17: B006
A18: IB4c | G18: =IF(F18="","",TODAY()-F18) | H18: =IF(G18="","",ROUND(G18/30.44,1)) | I18: =IF(OR(F18="",D18="TP",D18=""),"",IF(G18<Settings!$B$4,"Too young",IF(G18<=Settings!$B$5,"Yes","Too old")))
A19: IB4d | B19: CX3CR1KO (-/-) | C19: CX3CR1KO(-/-) | D19: F | E19: 2 | F19: 46274 | G19: =IF(F19="","",TODAY()-F19) -> 47 | H19: =IF(G19="","",ROUND(G19/30.44,1)) -> 1.5 | I19: =IF(OR(F19="",D19="TP",D19=""),"",IF(G19<Settings!$B$4,"Too young",IF(G19<=Settings!$B$5,"Yes","Too old"))) -> Too young | J19: B021 | K19: B022 | N19: Cx3cr1-KO: hom
A20: IB4e | B20: GCaMP3-Thy1 + CarCre | C20: GC3Thy1+CarCre | D20: M | E20: 1 | F20: 46144 | G20: =IF(F20="","",TODAY()-F20) -> 177 | H20: =IF(G20="","",ROUND(G20/30.44,1)) -> 5.8 | I20: =IF(OR(F20="",D20="TP",D20=""),"",IF(G20<Settings!$B$4,"Too young",IF(G20<=Settings!$B$5,"Yes","Too old"))) -> Yes
A21: IB5a | B21: GCaMP3-Thy1 | C21: GCaMP3Thy1 | D21: F | E21: 3 | F21: 46228 | G21: =IF(F21="","",TODAY()-F21) -> 93 | H21: =IF(G21="","",ROUND(G21/30.44,1)) -> 3.1 | I21: =IF(OR(F21="",D21="TP",D21=""),"",IF(G21<Settings!$B$4,"Too young",IF(G21<=Settings!$B$5,"Yes","Too old"))) -> Yes
A22: IB5b | G22: =IF(F22="","",TODAY()-F22) | H22: =IF(G22="","",ROUND(G22/30.44,1)) | I22: =IF(OR(F22="",D22="TP",D22=""),"",IF(G22<Settings!$B$4,"Too young",IF(G22<=Settings!$B$5,"Yes","Too old")))
A23: IB5c | B23: CX3CR1KO + Bl6 | C23: CX3CR1KO+Bl6 | D23: F | E23: 1 | F23: 46241 | G23: =IF(F23="","",TODAY()-F23) -> 80 | H23: =IF(G23="","",ROUND(G23/30.44,1)) -> 2.6 | I23: =IF(OR(F23="",D23="TP",D23=""),"",IF(G23<Settings!$B$4,"Too young",IF(G23<=Settings!$B$5,"Yes","Too old"))) -> Yes | J23: B005 | K23: B006
A24: IB5d | B24: CX3CR1KO + Bl6 | C24: CX3CR1KO+Bl6 | D24: F | E24: 2 | F24: 46218 | G24: =IF(F24="","",TODAY()-F24) -> 103 | H24: =IF(G24="","",ROUND(G24/30.44,1)) -> 3.4 | I24: =IF(OR(F24="",D24="TP",D24=""),"",IF(G24<Settings!$B$4,"Too young",IF(G24<=Settings!$B$5,"Yes","Too old"))) -> Yes | J24: B005 | K24: B006
A25: IB5e | B25: GCaMP3-Thy1 + CarCre | C25: GC3Thy1+CarCre | D25: F | E25: 2 | F25: 46144 | G25: =IF(F25="","",TODAY()-F25) -> 177 | H25: =IF(G25="","",ROUND(G25/30.44,1)) -> 5.8 | I25: =IF(OR(F25="",D25="TP",D25=""),"",IF(G25<Settings!$B$4,"Too young",IF(G25<=Settings!$B$5,"Yes","Too old"))) -> Yes
A26: IB6a | B26: CX3CR1KO (-/-) | C26: CX3CR1KO(-/-) | D26: M | E26: 1 | F26: 46274 | G26: =IF(F26="","",TODAY()-F26) -> 47 | H26: =IF(G26="","",ROUND(G26/30.44,1)) -> 1.5 | I26: =IF(OR(F26="",D26="TP",D26=""),"",IF(G26<Settings!$B$4,"Too young",IF(G26<=Settings!$B$5,"Yes","Too old"))) -> Too young | J26: B021 | K26: B022 | N26: Cx3cr1-KO: hom
A27: IB6b | B27: CX3CR1KO + Bl6 | C27: CX3CR1KO + BL6 | D27: M | E27: 1 | F27: 45650 | G27: =IF(F27="","",TODAY()-F27) -> 671 | H27: =IF(G27="","",ROUND(G27/30.44,1)) -> 22 | I27: =IF(OR(F27="",D27="TP",D27=""),"",IF(G27<Settings!$B$4,"Too young",IF(G27<=Settings!$B$5,"Yes","Too old"))) -> Too old | L27: BOGI injektalt 07.16 (rAAVcreTdtom)
A28: IB6c | B28: Cx36KO + PV-Cre | C28: Cx36KOPVCre | D28: F | E28: 1 | F28: 46238 | G28: =IF(F28="","",TODAY()-F28) -> 83 | H28: =IF(G28="","",ROUND(G28/30.44,1)) -> 2.7 | I28: =IF(OR(F28="",D28="TP",D28=""),"",IF(G28<Settings!$B$4,"Too young",IF(G28<=Settings!$B$5,"Yes","Too old"))) -> Yes | J28: B012 | K28: B013
A29: IB6d | B29: Cx36KO + PV-Cre | C29: Cx36KOPVCre | D29: M | E29: 2 | F29: 46238 | G29: =IF(F29="","",TODAY()-F29) -> 83 | H29: =IF(G29="","",ROUND(G29/30.44,1)) -> 2.7 | I29: =IF(OR(F29="",D29="TP",D29=""),"",IF(G29<Settings!$B$4,"Too young",IF(G29<=Settings!$B$5,"Yes","Too old"))) -> Yes | J29: B012 | K29: B013
A30: IB6e | B30: Cas9 + PV-Cre | C30: Cas9 + PVCre | D30: F | E30: 2 | F30: 46284 | G30: =IF(F30="","",TODAY()-F30) -> 37 | H30: =IF(G30="","",ROUND(G30/30.44,1)) -> 1.2 | I30: =IF(OR(F30="",D30="TP",D30=""),"",IF(G30<Settings!$B$4,"Too young",IF(G30<=Settings!$B$5,"Yes","Too old"))) -> Too young | J30: B025 | K30: B026 | L30: Csaba
A31: IB7a | G31: =IF(F31="","",TODAY()-F31) | H31: =IF(G31="","",ROUND(G31/30.44,1)) | I31: =IF(OR(F31="",D31="TP",D31=""),"",IF(G31<Settings!$B$4,"Too young",IF(G31<=Settings!$B$5,"Yes","Too old")))
A32: IB7b | G32: =IF(F32="","",TODAY()-F32) | H32: =IF(G32="","",ROUND(G32/30.44,1)) | I32: =IF(OR(F32="",D32="TP",D32=""),"",IF(G32<Settings!$B$4,"Too young",IF(G32<=Settings!$B$5,"Yes","Too old")))
A33: IB7c | B33: C57Bl6J | C33: CX3CR1KO + BL6 | D33: M | E33: 1 | F33: 45828 | G33: =IF(F33="","",TODAY()-F33) -> 493 | H33: =IF(G33="","",ROUND(G33/30.44,1)) -> 16.2 | I33: =IF(OR(F33="",D33="TP",D33=""),"",IF(G33<Settings!$B$4,"Too young",IF(G33<=Settings!$B$5,"Yes","Too old"))) -> Too old | L33: Former pair: female removed (card 2026-10-25). Male B010, over age
A34: IB7d | B34: Cas9 + PV-Cre | C34: Cas9 + PVCre | D34: M | E34: 3 | F34: 46053 | G34: =IF(F34="","",TODAY()-F34) -> 268 | H34: =IF(G34="","",ROUND(G34/30.44,1)) -> 8.8 | I34: =IF(OR(F34="",D34="TP",D34=""),"",IF(G34<Settings!$B$4,"Too young",IF(G34<=Settings!$B$5,"Yes","Too old"))) -> Too old | L34: Csaba
A35: IB7e | B35: GCaMP3-Thy1 | C35: GCaMP3Thy1 | D35: M | E35: 2 | F35: 46293 | G35: =IF(F35="","",TODAY()-F35) -> 28 | H35: =IF(G35="","",ROUND(G35/30.44,1)) -> 0.9 | I35: =IF(OR(F35="",D35="TP",D35=""),"",IF(G35<Settings!$B$4,"Too young",IF(G35<=Settings!$B$5,"Yes","Too old"))) -> Too young | J35: B023 | K35: B024
A36: IB8a | G36: =IF(F36="","",TODAY()-F36) | H36: =IF(G36="","",ROUND(G36/30.44,1)) | I36: =IF(OR(F36="",D36="TP",D36=""),"",IF(G36<Settings!$B$4,"Too young",IF(G36<=Settings!$B$5,"Yes","Too old")))
A37: IB8b | G37: =IF(F37="","",TODAY()-F37) | H37: =IF(G37="","",ROUND(G37/30.44,1)) | I37: =IF(OR(F37="",D37="TP",D37=""),"",IF(G37<Settings!$B$4,"Too young",IF(G37<=Settings!$B$5,"Yes","Too old")))
A38: IB8c | B38: FL-Cx36KO | C38: FL-Cx36KO | D38: M | E38: 4 | F38: 46286 | G38: =IF(F38="","",TODAY()-F38) -> 35 | H38: =IF(G38="","",ROUND(G38/30.44,1)) -> 1.1 | I38: =IF(OR(F38="",D38="TP",D38=""),"",IF(G38<Settings!$B$4,"Too young",IF(G38<=Settings!$B$5,"Yes","Too old"))) -> Too young | J38: B016 | K38: B017
A39: IB8d | B39: FL-Cx36KO | C39: FL-Cx36KO | D39: F | E39: 4 | F39: 46286 | G39: =IF(F39="","",TODAY()-F39) -> 35 | H39: =IF(G39="","",ROUND(G39/30.44,1)) -> 1.1 | I39: =IF(OR(F39="",D39="TP",D39=""),"",IF(G39<Settings!$B$4,"Too young",IF(G39<=Settings!$B$5,"Yes","Too old"))) -> Too young | J39: B016 | K39: B017
A40: IB8e | B40: GCaMP3-Thy1 | C40: GCaMP3Thy1 | D40: F | E40: 5 | F40: 46293 | G40: =IF(F40="","",TODAY()-F40) -> 28 | H40: =IF(G40="","",ROUND(G40/30.44,1)) -> 0.9 | I40: =IF(OR(F40="",D40="TP",D40=""),"",IF(G40<Settings!$B$4,"Too young",IF(G40<=Settings!$B$5,"Yes","Too old"))) -> Too young | J40: B023 | K40: B024
...

Sheet Mice
A1: Mouse ID | B1: Cage | C1: Ear mark | D1: Line | E1: Sex | F1: Born | G1: Sire ID | H1: Dam ID | I1: Genotype | J1: Status | K1: Status date | L1: Breeder ID | M1: Notes | N1: Needs genotyping
A2: M0001 | B2: IB1b | C2: none | D2: CX3CR1KO + Bl6 | E2: F | F2: 46269 | G2: B005 | H2: B006 | J2: Alive | M2: Ear mark assigned automatically - check the ears
A3: M0002 | B3: IB1b | C3: L | D3: CX3CR1KO + Bl6 | E3: F | F3: 46269 | G3: B005 | H3: B006 | J3: Alive | M3: Ear mark assigned automatically - check the ears
A4: M0003 | B4: IB1c | C4: none | D4: CX3CR1KO + Bl6 | E4: M | F4: 46269 | G4: B005 | H4: B006 | J4: Alive | M4: Ear mark assigned automatically - check the ears
A5: M0004 | B5: IB1c | C5: L | D5: CX3CR1KO + Bl6 | E5: M | F5: 46269 | G5: B005 | H5: B006 | J5: Alive | M5: Ear mark assigned automatically - check the ears
A6: M0005 | B6: IB2b | C6: none | D6: GCaMP3-Thy1 + CarCre | E6: F | F6: 46269 | G6: B018 | J6: Alive | M6: Ear mark assigned automatically - check the ears
A7: M0006 | B7: IB2b | C7: L | D7: GCaMP3-Thy1 + CarCre | E7: F | F7: 46269 | G7: B018 | J7: Alive | M7: Ear mark assigned automatically - check the ears
A8: M0007 | B8: IB2b | C8: R | D8: GCaMP3-Thy1 + CarCre | E8: F | F8: 46269 | G8: B018 | J8: Alive | M8: Ear mark assigned automatically - check the ears
A9: M0008 | B9: IB3a | C9: none | D9: GCaMP3-Thy1 | E9: F | F9: 46272 | G9: B002 | H9: B001 | J9: Alive | M9: Ear mark assigned automatically - check the ears
A10: M0009 | B10: IB3a | C10: L | D10: GCaMP3-Thy1 | E10: F | F10: 46272 | G10: B002 | H10: B001 | J10: Alive | M10: Ear mark assigned automatically - check the ears
A11: M0010 | B11: IB3b | C11: none | D11: C57Bl6J | E11: F | F11: 45943 | J11: Alive | M11: Ear mark assigned automatically - check the ears
A12: M0011 | B12: IB3b | C12: L | D12: C57Bl6J | E12: F | F12: 45943 | J12: Alive | M12: Ear mark assigned automatically - check the ears
A13: M0012 | B13: IB3b | C13: R | D13: C57Bl6J | E13: F | F13: 45943 | J13: Alive | M13: Ear mark assigned automatically - check the ears
A14: M0013 | B14: IB3b | C14: LR | D14: C57Bl6J | E14: F | F14: 45943 | J14: Alive | M14: Ear mark assigned automatically - check the ears
A15: M0014 | B15: IB3c | C15: none | D15: GCaMP3-Thy1 | E15: M | F15: 46272 | G15: B002 | H15: B001 | J15: Alive | M15: Ear mark assigned automatically - check the ears
A16: M0015 | B16: IB3c | C16: L | D16: GCaMP3-Thy1 | E16: M | F16: 46272 | G16: B002 | H16: B001 | J16: Alive | M16: Ear mark assigned automatically - check the ears
A17: M0016 | B17: IB3c | C17: R | D17: GCaMP3-Thy1 | E17: M | F17: 46272 | G17: B002 | H17: B001 | J17: Alive | M17: Ear mark assigned automatically - check the ears
A18: M0017 | B18: IB4a | C18: none | D18: C57Bl6J | E18: M | F18: 45943 | J18: Alive | M18: Ear mark assigned automatically - check the ears
A19: M0018 | B19: IB4a | C19: L | D19: C57Bl6J | E19: M | F19: 45943 | J19: Alive | M19: Ear mark assigned automatically - check the ears
A20: M0019 | B20: IB4b | C20: none | D20: CX3CR1KO + Bl6 | E20: M | F20: 46241 | G20: B005 | H20: B006 | J20: Alive | M20: Ear mark assigned automatically - check the ears
A21: M0020 | B21: IB4b | C21: L | D21: CX3CR1KO + Bl6 | E21: M | F21: 46241 | G21: B005 | H21: B006 | J21: Alive | M21: Ear mark assigned automatically - check the ears
A22: M0021 | B22: IB4d | C22: none | D22: CX3CR1KO (-/-) | E22: F | F22: 46274 | G22: B021 | H22: B022 | I22: Cx3cr1-KO: hom | J22: Alive | M22: Ear mark assigned automatically - check the ears
A23: M0022 | B23: IB4d | C23: L | D23: CX3CR1KO (-/-) | E23: F | F23: 46274 | G23: B021 | H23: B022 | I23: Cx3cr1-KO: hom | J23: Alive | M23: Ear mark assigned automatically - check the ears
A24: M0023 | B24: IB4e | C24: none | D24: GCaMP3-Thy1 + CarCre | E24: M | F24: 46144 | J24: Alive | M24: Ear mark assigned automatically - check the ears
A25: M0024 | B25: IB5a | C25: none | D25: GCaMP3-Thy1 | E25: F | F25: 46228 | J25: Alive | M25: Ear mark assigned automatically - check the ears
A26: M0025 | B26: IB5a | C26: L | D26: GCaMP3-Thy1 | E26: F | F26: 46228 | J26: Alive | M26: Ear mark assigned automatically - check the ears
A27: M0026 | B27: IB5a | C27: R | D27: GCaMP3-Thy1 | E27: F | F27: 46228 | J27: Alive | M27: Ear mark assigned automatically - check the ears
A28: M0027 | B28: IB5c | C28: none | D28: CX3CR1KO + Bl6 | E28: F | F28: 46241 | G28: B005 | H28: B006 | J28: Alive | M28: Ear mark assigned automatically - check the ears
A29: M0028 | B29: IB5d | C29: none | D29: CX3CR1KO + Bl6 | E29: F | F29: 46218 | G29: B005 | H29: B006 | J29: Alive | M29: Ear mark assigned automatically - check the ears
A30: M0029 | B30: IB5d | C30: L | D30: CX3CR1KO + Bl6 | E30: F | F30: 46218 | G30: B005 | H30: B006 | J30: Alive | M30: Ear mark assigned automatically - check the ears
A31: M0030 | B31: IB5e | C31: none | D31: GCaMP3-Thy1 + CarCre | E31: F | F31: 46144 | J31: Alive | M31: Ear mark assigned automatically - check the ears
A32: M0031 | B32: IB5e | C32: L | D32: GCaMP3-Thy1 + CarCre | E32: F | F32: 46144 | J32: Alive | M32: Ear mark assigned automatically - check the ears
A33: M0032 | B33: IB6a | C33: none | D33: CX3CR1KO (-/-) | E33: M | F33: 46274 | G33: B021 | H33: B022 | I33: Cx3cr1-KO: hom | J33: Alive | M33: Ear mark assigned automatically - check the ears
A34: M0033 | B34: IB6b | C34: none | D34: CX3CR1KO + Bl6 | E34: M | F34: 45650 | J34: Alive | M34: Ear mark assigned automatically - check the ears
A35: M0034 | B35: IB6c | C35: none | D35: Cx36KO + PV-Cre | E35: F | F35: 46238 | G35: B012 | H35: B013 | J35: Alive | M35: Ear mark assigned automatically - check the ears
A36: M0035 | B36: IB6d | C36: none | D36: Cx36KO + PV-Cre | E36: M | F36: 46238 | G36: B012 | H36: B013 | J36: Alive | M36: Ear mark assigned automatically - check the ears
A37: M0036 | B37: IB6d | C37: L | D37: Cx36KO + PV-Cre | E37: M | F37: 46238 | G37: B012 | H37: B013 | J37: Alive | M37: Ear mark assigned automatically - check the ears
A38: M0037 | B38: IB6e | C38: none | D38: Cas9 + PV-Cre | E38: F | F38: 46284 | G38: B025 | H38: B026 | J38: Alive | M38: Ear mark assigned automatically - check the ears
A39: M0038 | B39: IB6e | C39: L | D39: Cas9 + PV-Cre | E39: F | F39: 46284 | G39: B025 | H39: B026 | J39: Alive | M39: Ear mark assigned automatically - check the ears
A40: M0039 | B40: IB7c | C40: none | D40: C57Bl6J | E40: M | F40: 45828 | J40: Alive | L40: B010 | M40: Ear mark assigned automatically - check the ears
...

Sheet Lines
A1: Line | B1: Allowed partner lines | C1: Must keep (Y) | D1: Genetic background | E1: Last fresh vendor B6 introduced | F1: Notes | G1: Active pairs | H1: Pairs OVER AGE | I1: Pairs replace soon | J1: Candidate M cages | K1: Candidate F cages | L1: Line status | M1: Loci tracked (; separated) | N1: Made of (lines, ; separated)
A2: C57Bl6J | C2: Y | D2: C57BL/6J (JAX 000664) | F2: Also used as outcross partner | G2: =COUNTIFS(Pairs!$B$2:$B$1000,A2,Pairs!$G$2:$G$1000,"Active") -> 0 | H2: =COUNTIFS(Pairs!$B$2:$B$1000,A2,Pairs!$M$2:$M$1000,"OVER AGE") -> 0 | I2: =COUNTIFS(Pairs!$B$2:$B$1000,A2,Pairs!$M$2:$M$1000,"Replace soon") -> 0 | J2: =COUNTIFS(Cages!$B$2:$B$1000,A2,Cages!$D$2:$D$1000,"M",Cages!$I$2:$I$1000,"Yes") -> 0 | K2: =COUNTIFS(Cages!$B$2:$B$1000,A2,Cages!$D$2:$D$1000,"F",Cages!$I$2:$I$1000,"Yes") -> 0 | L2: =IF(AND(C2="Y",G2=0),"NO ACTIVE PAIR",IF(H2>0,"Pair over age",IF(I2>0,"Plan replacement",""))) -> NO ACTIVE PAIR
A3: PV-Cre | C3: Y | D3: C57BL/6 | G3: =COUNTIFS(Pairs!$B$2:$B$1000,A3,Pairs!$G$2:$G$1000,"Active") -> 1 | H3: =COUNTIFS(Pairs!$B$2:$B$1000,A3,Pairs!$M$2:$M$1000,"OVER AGE") -> 1 | I3: =COUNTIFS(Pairs!$B$2:$B$1000,A3,Pairs!$M$2:$M$1000,"Replace soon") -> 0 | J3: =COUNTIFS(Cages!$B$2:$B$1000,A3,Cages!$D$2:$D$1000,"M",Cages!$I$2:$I$1000,"Yes") -> 1 | K3: =COUNTIFS(Cages!$B$2:$B$1000,A3,Cages!$D$2:$D$1000,"F",Cages!$I$2:$I$1000,"Yes") -> 2 | L3: =IF(AND(C3="Y",G3=0),"NO ACTIVE PAIR",IF(H3>0,"Pair over age",IF(I3>0,"Plan replacement",""))) -> Pair over age | M3: PV-Cre
A4: GCaMP3-Thy1 | C4: Y | D4: B6;CBA (JAX 017893) | F4: Mixed background | G4: =COUNTIFS(Pairs!$B$2:$B$1000,A4,Pairs!$G$2:$G$1000,"Active") -> 2 | H4: =COUNTIFS(Pairs!$B$2:$B$1000,A4,Pairs!$M$2:$M$1000,"OVER AGE") -> 0 | I4: =COUNTIFS(Pairs!$B$2:$B$1000,A4,Pairs!$M$2:$M$1000,"Replace soon") -> 1 | J4: =COUNTIFS(Cages!$B$2:$B$1000,A4,Cages!$D$2:$D$1000,"M",Cages!$I$2:$I$1000,"Yes") -> 1 | K4: =COUNTIFS(Cages!$B$2:$B$1000,A4,Cages!$D$2:$D$1000,"F",Cages!$I$2:$I$1000,"Yes") -> 2 | L4: =IF(AND(C4="Y",G4=0),"NO ACTIVE PAIR",IF(H4>0,"Pair over age",IF(I4>0,"Plan replacement",""))) -> Plan replacement | M4: Thy1-GCaMP3
A5: FL-Cx36KO | C5: Y | G5: =COUNTIFS(Pairs!$B$2:$B$1000,A5,Pairs!$G$2:$G$1000,"Active") -> 1 | H5: =COUNTIFS(Pairs!$B$2:$B$1000,A5,Pairs!$M$2:$M$1000,"OVER AGE") -> 0 | I5: =COUNTIFS(Pairs!$B$2:$B$1000,A5,Pairs!$M$2:$M$1000,"Replace soon") -> 0 | J5: =COUNTIFS(Cages!$B$2:$B$1000,A5,Cages!$D$2:$D$1000,"M",Cages!$I$2:$I$1000,"Yes") -> 0 | K5: =COUNTIFS(Cages!$B$2:$B$1000,A5,Cages!$D$2:$D$1000,"F",Cages!$I$2:$I$1000,"Yes") -> 1 | L5: =IF(AND(C5="Y",G5=0),"NO ACTIVE PAIR",IF(H5>0,"Pair over age",IF(I5>0,"Plan replacement",""))) | M5: Cx36-flox
A6: Cx36KO + PV-Cre | C6: Y | F6: Was "CX36KO_PVCRE" / "Cx36KOPVCre" | G6: =COUNTIFS(Pairs!$B$2:$B$1000,A6,Pairs!$G$2:$G$1000,"Active") -> 1 | H6: =COUNTIFS(Pairs!$B$2:$B$1000,A6,Pairs!$M$2:$M$1000,"OVER AGE") -> 0 | I6: =COUNTIFS(Pairs!$B$2:$B$1000,A6,Pairs!$M$2:$M$1000,"Replace soon") -> 0 | J6: =COUNTIFS(Cages!$B$2:$B$1000,A6,Cages!$D$2:$D$1000,"M",Cages!$I$2:$I$1000,"Yes") -> 1 | K6: =COUNTIFS(Cages!$B$2:$B$1000,A6,Cages!$D$2:$D$1000,"F",Cages!$I$2:$I$1000,"Yes") -> 1 | L6: =IF(AND(C6="Y",G6=0),"NO ACTIVE PAIR",IF(H6>0,"Pair over age",IF(I6>0,"Plan replacement",""))) | M6: Cx36-flox; PV-Cre | N6: FL-Cx36KO; PV-Cre
A7: CX3CR1KO (-/-) | G7: =COUNTIFS(Pairs!$B$2:$B$1000,A7,Pairs!$G$2:$G$1000,"Active") -> 2 | H7: =COUNTIFS(Pairs!$B$2:$B$1000,A7,Pairs!$M$2:$M$1000,"OVER AGE") -> 0 | I7: =COUNTIFS(Pairs!$B$2:$B$1000,A7,Pairs!$M$2:$M$1000,"Replace soon") -> 1 | J7: =COUNTIFS(Cages!$B$2:$B$1000,A7,Cages!$D$2:$D$1000,"M",Cages!$I$2:$I$1000,"Yes") -> 0 | K7: =COUNTIFS(Cages!$B$2:$B$1000,A7,Cages!$D$2:$D$1000,"F",Cages!$I$2:$I$1000,"Yes") -> 1 | L7: =IF(AND(C7="Y",G7=0),"NO ACTIVE PAIR",IF(H7>0,"Pair over age",IF(I7>0,"Plan replacement",""))) -> Plan replacement | M7: Cx3cr1-KO
A8: CX3CR1KO + Bl6 | B8: CX3CR1KO + Bl6; C57Bl6J | D8: C57BL/6J outcross | F8: Pairs use a Bl6 partner | G8: =COUNTIFS(Pairs!$B$2:$B$1000,A8,Pairs!$G$2:$G$1000,"Active") -> 4 | H8: =COUNTIFS(Pairs!$B$2:$B$1000,A8,Pairs!$M$2:$M$1000,"OVER AGE") -> 3 | I8: =COUNTIFS(Pairs!$B$2:$B$1000,A8,Pairs!$M$2:$M$1000,"Replace soon") -> 0 | J8: =COUNTIFS(Cages!$B$2:$B$1000,A8,Cages!$D$2:$D$1000,"M",Cages!$I$2:$I$1000,"Yes") -> 4 | K8: =COUNTIFS(Cages!$B$2:$B$1000,A8,Cages!$D$2:$D$1000,"F",Cages!$I$2:$I$1000,"Yes") -> 6 | L8: =IF(AND(C8="Y",G8=0),"NO ACTIVE PAIR",IF(H8>0,"Pair over age",IF(I8>0,"Plan replacement",""))) -> Pair over age | M8: Cx3cr1-KO
A9: GCaMP3-Thy1 + CarCre | F9: Was "GC3Thy1+CarCre" / "GCaMP3Thy1 + CarCre" | G9: =COUNTIFS(Pairs!$B$2:$B$1000,A9,Pairs!$G$2:$G$1000,"Active") -> 1 | H9: =COUNTIFS(Pairs!$B$2:$B$1000,A9,Pairs!$M$2:$M$1000,"OVER AGE") -> 0 | I9: =COUNTIFS(Pairs!$B$2:$B$1000,A9,Pairs!$M$2:$M$1000,"Replace soon") -> 1 | J9: =COUNTIFS(Cages!$B$2:$B$1000,A9,Cages!$D$2:$D$1000,"M",Cages!$I$2:$I$1000,"Yes") -> 4 | K9: =COUNTIFS(Cages!$B$2:$B$1000,A9,Cages!$D$2:$D$1000,"F",Cages!$I$2:$I$1000,"Yes") -> 3 | L9: =IF(AND(C9="Y",G9=0),"NO ACTIVE PAIR",IF(H9>0,"Pair over age",IF(I9>0,"Plan replacement",""))) -> Plan replacement | M9: Thy1-GCaMP3; CarCre | N9: GCaMP3-Thy1; CarCre
A10: Cas9 + PV-Cre | F10: Csaba | G10: =COUNTIFS(Pairs!$B$2:$B$1000,A10,Pairs!$G$2:$G$1000,"Active") -> 1 | H10: =COUNTIFS(Pairs!$B$2:$B$1000,A10,Pairs!$M$2:$M$1000,"OVER AGE") -> 1 | I10: =COUNTIFS(Pairs!$B$2:$B$1000,A10,Pairs!$M$2:$M$1000,"Replace soon") -> 0 | J10: =COUNTIFS(Cages!$B$2:$B$1000,A10,Cages!$D$2:$D$1000,"M",Cages!$I$2:$I$1000,"Yes") -> 0 | K10: =COUNTIFS(Cages!$B$2:$B$1000,A10,Cages!$D$2:$D$1000,"F",Cages!$I$2:$I$1000,"Yes") -> 0 | L10: =IF(AND(C10="Y",G10=0),"NO ACTIVE PAIR",IF(H10>0,"Pair over age",IF(I10>0,"Plan replacement",""))) -> Pair over age | M10: Cas9; PV-Cre | N10: Cas9; PV-Cre

Sheet Litters
A1: Litter born | B1: Pair cage | C1: Sire ID | D1: Dam ID | E1: Pups born | F1: Weaned on | G1: Weaned M | H1: Weaned F | I1: Wean cage M | J1: Wean cage F | K1: Notes

Sheet Procedures
A1: Date | B1: Cage | C1: Animal ID | D1: Line | E1: Sex | F1: Mice | G1: Born | H1: Procedure | I1: Details | J1: Person | K1: Notes

Sheet Terminated
A1: Date | B1: Cage | C1: Animal ID | D1: Line | E1: Sex | F1: Mice | G1: Born | H1: Age (days) | I1: Outcome | J1: Reason / use | K1: Project | L1: Person | M1: Sire ID | N1: Dam ID | O1: Genotype | P1: Procedures done | Q1: Notes

Sheet Issues
A1: Cage | B1: Problem found | C1: What was done in conversion | D1: Action needed | E1: Done?
A2: IB3b | B2: Note says "terminate or use" | D2: Use or terminate, then clear the cage row
A3: IB4a | B3: Note says "terminate or use" | D3: Use or terminate, then clear the cage row
A4: IIA2b | B4: Note says "need to genotype" | D4: Genotype
A5: IIA2c | B5: Note says "terminate or use" | D5: Use or terminate, then clear the cage row
A6: IIA2d | B6: Note says "terminate" | D6: Use or terminate, then clear the cage row
A7: IIA3e | B7: Invalid date "2025.15.05" (month 15) | C7: Read as 2025-05-15 (day and month swapped) | Resolved 2026-10-25: Card: male born 2025.12.05 | D7: Check the real birth date | E7: Done
A8: IIA4b | B8: Note says "terminate or use" | D8: Use or terminate, then clear the cage row
A9: IIA4e | B9: Breeding pair has only one birth date | C9: Used 2024-08-20 for both animals | Resolved 2026-10-25: Card: M 2025.08.20, F 2025.08.05 | D9: Enter the real male and female birth dates on Breeders | E9: Done
A10: IIA6d | B10: Note says "terminate!!" | D10: Use or terminate, then clear the cage row
A11: IIA6e | B11: Breeding pair has only one birth date | C11: Used 2026-07-26 for both animals | Resolved 2026-10-25: Card: both born 2026.07.26 | D11: Enter the real male and female birth dates on Breeders | E11: Done
A12: IIA8c | B12: Note says "terminate!!" | D12: Use or terminate, then clear the cage row
A13: IIA8d | B13: Note says "terminate!!" | D13: Use or terminate, then clear the cage row
A14: (all) | B14: Line name written several ways: "CX3CR1KO(-/-)" | C14: Unified to "CX3CR1KO (-/-)" (original kept in "Line as written") | D14: Check the merge is right
A15: (all) | B15: Line name written several ways: "CX3CR1KO + BL6", "CX3CR1KO+Bl6" | C15: Unified to "CX3CR1KO + Bl6" (original kept in "Line as written") | D15: Check the merge is right
A16: (all) | B16: Line name written several ways: "Cas9 + PVCre" | C16: Unified to "Cas9 + PV-Cre" (original kept in "Line as written") | D16: Check the merge is right
A17: (all) | B17: Line name written several ways: "CX36KO_PVCRE", "Cx36KOPVCre" | C17: Unified to "Cx36KO + PV-Cre" (original kept in "Line as written") | D17: Check the merge is right
A18: (all) | B18: Line name written several ways: "GCaMP3Thy1" | C18: Unified to "GCaMP3-Thy1" (original kept in "Line as written") | D18: Check the merge is right
A19: (all) | B19: Line name written several ways: "GC3Thy1+CarCre", "GCaMP3Thy1 + CarCre" | C19: Unified to "GCaMP3-Thy1 + CarCre" (original kept in "Line as written") | D19: Check the merge is right
A20: (all) | B20: Line name written several ways: "PVCRE", "PVCre" | C20: Unified to "PV-Cre" (original kept in "Line as written") | D20: Check the merge is right
A21: IB2e, IB3d, IIA5b | B21: Three pairs list a Bl6 male born 2025-10-13 | C21: Treated as three different males | Resolved 2026-10-25: Cards: separate males from the 2025-10-13 Bl6 batch (15) | D21: Confirm they are three animals, not one moved between cages | E21: Done
A22: IIA6e | B22: Breeding pair are littermates (both born 2026-07-26 in II/A/4/a, per cage card) | C22: Parents B021 x B022 entered for both | D22: Full-sib mating: replace one partner if CX3CR1 (-/-) can be outcrossed to another (-/-) line
A23: IB7c | B23: Card shows the female crossed off; one male left | C23: Pair set to Ended, both retired, cage = 1 Bl6 M | D23: Use or terminate the male (16 months)
A24: (cages) | B24: Parents of 27 stock cages filled from the card "Származási hely" (purple IDs on Cages) | C24: Only where the origin is a current pair and the birth date fits | D24: Spot-check a few; correct any wrong link
A25: IB2b, IIA3a | B25: Born in trio IIA3e (1 M + 2 F): mother unknown | C25: Sire B018 entered, dam left blank | D25: If known, enter B019 or B020 as Dam
A26: IIA3d | B26: Card origin II/A/3/c, born 2026-08-11: current IIA3c female would have been ~5 weeks at mating | C26: No parents entered | D26: Probably an earlier pair in IIA3c - check
A27: IIA1d, IIA4a, IIA6b, IIA7c, IIA8e | B27: Cage card not readable in the video | C27: Unchanged | D27: Check these cards

Sheet Settings
A1: Setting | B1: Value | C1: What it does
A2: Max breeder age (days) | B2: 365 | C2: Breeders at or above this age are flagged OVER AGE
A3: Warn this many days before | B3: 60 | C3: Flag "Replace soon" this long before MaxAge, so replacements can be set aside
A4: Min breeding age (days) | B4: 49 | C4: Younger animals are flagged "Too young" (7 weeks)
A5: Max age to start a new breeder (days) | B5: 180 | C5: Stock cages older than this are not offered as breeder candidates
A7: Last cage check | B7: 46320 | C7: Date of the last physical check (cage-card videos 2026-10-25)

Sheet Strains
B2: Rövid név | C2: JAX | D2: genotype | E2: link | F2: Basic WT Strain | G2: OTHER
A3: BASIC LINES | B3: C57Bl6J | C3: 000664 | D3: WT | E3: 000664 - C57BL/6J (jax.org) | F3: C57BL6
B4: PV-Cre | C4: 17320 | D4: Pvalbtm1(cre)Arbr; PV-IRES-Cre | E4: www.jax.org/strain/017320 | F4: C57BL6
B5: Thy1-Cre | C5: similar to: 006143, KOKI | D5: Tg(Thy1-cre)1Vln | E5: 006143 - FVB/N-Tg(Thy1-cre)1Vln/J (jax.org) | F5: FVB/AntFx
B6: GCaMP3-Thy1 | C6: 017893 | D6: B6;CBA-Tg(Thy1-GCaMP3)6Gfng/J | E6: https://www.jax.org/strain/017893 | F6: C57BL6
B7: tdTom-flox | C7: 007905 | D7: Gt(ROSA)26Sor_CAG/LSL_tdTomato Ai9 | E7: 007905 - B6;129S6-Gt(ROSA)26Sor<tm9(CAG-tdTomato)Hze>/J (jax.org) | F7: C57BL6
A11: CROSSED LINES | B11: Thy1/GC6s | C11: See KOKI | D11: Thy1-Cre x GCaMP6s | E11: http://kac.koki.hu/menu.php?menuid=ogr_vonal | F11: C57BL6 | G11: Thy1/gcamp6s Tg; KOKI
B12: Thy1Cre-tdTom | C12: SEE BASIC LINES | D12: Thy1-Cre x tdTom-flox | F12: FVB/AntFx x C57Bl6 | G12: Crossed in SZKK by TKÖ
B13: PVCre-tdTom | C13: SEE BASIC LINES | D13: PV-Cre x tdTom-flox | F13: C57BL6 | G13: Crossed in SZKK by TKÖ
B14: ArchR-PvCre | C14: Discontinued | D14: PV-Cre x Archeorhodopsin-GFP | E14: Discontinued | F14: Discontinued | G14: Crossed in SZKK by TKÖ, +
B18: Former Strains
B19: Thy1-GCaMP6s | C19: 24275 | D19: C57BL/6J-Tg(Thy1-GCaMP6s)GP4.3Dkim/J | E19: https://www.jax.org/strain/24275 | F19: C57BL6 | G19: +

Sheet Archive Mice 2026-10-21
B1: Checked | D1: 46316
B2: Cage | C2: Old cage | D2: Line | E2: Gender | F2: Number | G2: Birth | H2: Old | I2: Note | J2: Lefoglalva | L2: Bl6 | M2: =COUNTIF(D3:D83,"Bl6") -> 0
B3: IB1b | D3: CX3CR1KO+Bl6 | E3: F | F3: 2 | G3: 46269
B4: IB1c | D4: CX3CR1KO+Bl6 | E4: M | F4: 2 | G4: 46269
B5: IB1d
B6: IB1e
B7: IB2a | D7: GCaMP3Thy1 | E7: TP | F7: 2 | G7: 2026.01.26(F)+2026.01.07(M)
B8: IB2b | D8: GCaMP3Thy1 + CarCre | E8: F | F8: 3 | G8: 46269
B9: IB2c
B10: IB2d | D10: CX3CR1KO + BL6 | E10: TP | F10: 2 | G10: 2026.06.20(F,Bl6)+2026.04.29(M)
B11: IB2e | D11: CX3CR1KO + BL6 | E11: TP | F11: 2 | G11: 2025.10.13 (M,Bl6)+2025.12.31 (F)
B12: IB3a | D12: GCaMP3Thy1 | E12: F | F12: 2 | G12: 46272
B13: IB3b | D13: C57Bl6J | E13: F | F13: 4 | G13: 45943 | I13: terminate or use
B14: IB3c | D14: GCaMP3Thy1 | E14: M | F14: 3 | G14: 46272
B15: IB3d | D15: CX3CR1KO + BL6 | E15: TP | F15: 3 | G15: 2025.10.13 (M,Bl6)+2026.06.11 (2F)
B16: IB3e
B17: IB4a | D17: C57Bl6J | E17: M | F17: 2 | G17: 45943 | I17: terminate or use
B18: IB4b | D18: CX3CR1KO+Bl6 | E18: M | F18: 2 | G18: 46241
B19: IB4c
B20: IB4d | D20: CX3CR1KO(-/-) | E20: F | F20: 2 | G20: 46274
B21: IB4e | D21: GC3Thy1+CarCre | E21: M | F21: 1 | G21: 46144
B22: IB5a | D22: GCaMP3Thy1 | E22: F | F22: 3 | G22: 46228
B23: IB5b
B24: IB5c | D24: CX3CR1KO+Bl6 | E24: F | F24: 1 | G24: 46241
B25: IB5d | D25: CX3CR1KO+Bl6 | E25: F | F25: 2 | G25: 46218
B26: IB5e | D26: GC3Thy1+CarCre | E26: F | F26: 2 | G26: 46144
B27: IB6a | D27: CX3CR1KO(-/-) | E27: M | F27: 1 | G27: 46274
B28: IB6b | D28: CX3CR1KO + BL6 | E28: M | F28: 1 | G28: 45650 | I28: BOGI injektalt 07.16 (rAAVcreTdtom)
B29: IB6c | D29: Cx36KOPVCre | E29: F | F29: 1 | G29: 46238
B30: IB6d | D30: Cx36KOPVCre | E30: M | F30: 2 | G30: 46238
B31: IB6e | D31: Cas9 + PVCre | E31: F | F31: 2 | G31: 46284 | I31: Csaba
B32: IB7a
B33: IB7b
B34: IB7c | D34: CX3CR1KO + BL6 | E34: TP | F34: 2 | G34: 2025.06.20 (M,Bl6)+2025.02.18 (F)
B35: IB7d | D35: Cas9 + PVCre | E35: M | F35: 3 | G35: 46053 | I35: Csaba
B36: IB7e | D36: GCaMP3Thy1 | E36: M | F36: 2 | G36: 46293
B37: IB8a
B38: IB8b
B39: IB8c | D39: FL-Cx36KO | E39: M | F39: 4 | G39: 46286
B40: IB8d | D40: FL-Cx36KO | E40: F | F40: 4 | G40: 46286
...

Sheet Archive Mice old
B1: Checked | C1: 45467
B2: Cage | C2: Line | D2: Gender | E2: Number | F2: Birth | G2: Old | H2: Note | I2: Lefoglalva | K2: Bl6 | L2: =COUNTIF(C3:C120,"Bl6") -> 0
B3: IA2a | C3: PvCre | D3: F | E3: 1 | F3: 45320 | K3: PV-Cre | L3: =COUNTIF(C3:C120,"PVCre") -> 29
B4: IA3c | K4: GCaMP3Thy1 | L4: =COUNTIF(C3:C120,"GCaMP3Thy1") -> 4
B5: IA3d | C5: C57BL6 | D5: F | E5: 3 | F5: 45514
B6: IA3e | C6: FLCX36_PVCRE | D6: M | E6: 5 | F6: 45541
B7: IA4a | K7: FlCx36-KO (hom) | L7: =COUNTIF(C3:C120,"FlCx36-KO (hom)") -> 1
B8: IA4b | K8: Calb2-Cre | L8: =COUNTIF(C3:C120,"Calb2-Cre") -> 9
B9: IA4c | K9: FL-Cx36KO (hom) + PVCre | L9: =COUNTIF(C3:C120,"FL-Cx36KO (hom) + PVCre") -> 0
B10: IA4d | K10: TdTom - Flox | L10: =COUNTIF(C3:C120,"TdTom - Flox") -> 0
B11: IA4e | K11: PVCre? | L11: =COUNTIF(C4:C121,"PVCre?") -> 2
B12: IA5a
B13: IA5b | C13: Calb2-Cre | D13: M | E13: 2 | F13: 45412
B14: IA5c | C14: CX36FL(?)_PvCre(?)_GC6STHY1(?) | D14: M | E14: 3 | F14: 45458 | H14: GENO | K14: Total Cage | L14: =COUNTA(C3:C185) -> 86
B15: IA5d | C15: Calb2-Cre | D15: F | E15: 2 | F15: 45411 | H15: Tamas AAV - 06,11 | I15: Tamás
B16: IA5e | C16: FLCx36KO_Cx36FLX_PvCre | D16: M | E16: 3 | F16: 45357 | H16: GENO - terminate
B17: IA6a | C17: PvCre? | D17: F | E17: 1 | F17: 45353
B18: IA6b | C18: Cx3CR1KO (-/-) | D18: F | E18: 3 | F18: 2024.09.20-25
B19: IA6c
